Workbook

Sheet Resumen
A1: ANÁLISIS HEURÍSTICO — PLATAFORMA ALUMCO
A2: Evaluación de las 10 heurísticas de Nielsen sobre el código de la aplicación (client/src, 20 pantallas). Escala 0 = sin problemas · 4 = catástrofe de usabilidad.
A4: Heurística | B4: Promedio | C4: Hallazgo principal
A5: 1. Visibilidad del estado del sistema | B5: ='Hoja 1'!B13 | C5: La generación con IA anuncia 30–60 segundos cuando el propio código estima ~3 minutos, sin barra de progreso.
A6: 2. Coincidencia sistema / mundo real | B6: ='Hoja 1'!B18 | C6: Vocabulario del sector bien resuelto; dos textos en voseo rioplatense rompen el tono chileno.
A7: 3. Control y libertad | B7: ='Hoja 1'!B27 | C7: El mecanismo de deshacer está construido pero se usa en una sola acción de toda la plataforma.
A8: 4. Coherencia y estándares | B8: ='Hoja 1'!B34 | C8: El admin de sede navega a URLs /jefatura/*; hay una ruta autorizada al profesor sin entrada en su menú.
A9: 5. Prevención de errores | B9: ='Hoja 1'!B41 | C9: Los campos obligatorios se marcan de forma irregular y no se valida el formato del RUT, que es la credencial de acceso.
A10: 6. Reconocer en lugar de recordar | B10: ='Hoja 1'!B46 | C10: Indicadores de paso muy sólidos; filtros y paginación se pierden al recargar por no vivir en la URL.
A11: 7. Flexibilidad y eficiencia | B11: ='Hoja 1'!B51 | C11: Casi sin atajos de teclado y sin personalización más allá de los ajustes de accesibilidad.
A12: 8. Estética y diseño minimalista | B12: ='Hoja 1'!B60 | C12: Mejor área evaluada: contraste documentado con ratios medidos y modo de alto contraste para dislexia.
A13: 9. Recuperación de errores | B13: ='Hoja 1'!B67 | C13: La sesión expirada redirige al login sin explicación; el rechazo de un certificado no se puede revertir.
A14: 10. Ayuda y documentación | B14: ='Hoja 1'!B76 | C14: Existe ayuda por rol, pero no hay ningún canal de soporte ni contacto dentro de la plataforma.
A15: PROMEDIO GENERAL | B15: ='Hoja 1'!B77
A17: PRIORIDADES (severidad 3)
A18: 1. Espera de la generación con IA: el mensaje subestima el tiempo real y no hay progreso por etapas ni opción de cancelar.
A19: 2. Deshacer ausente en acciones de alto coste: rechazar certificado, desasignar curso, eliminar protocolo.
A20: 3. Campos obligatorios sin marcado uniforme y sin validación de formato de RUT ni de correo.
A21: 4. Expiración de sesión: redirige al login sin explicar el motivo y se pierde el trabajo en curso.
A22: 5. Sin canal de soporte dentro de la plataforma: la ayuda remite a un encargado sin dar ningún medio de contacto.

Sheet Hoja 1
A3: ANÁLISIS HEURÍSTICO 10 PAUTAS DE NIELSEN
A4: PAUTA | B4: PUNTUACIÓN | C4: OBSERVACIONES | D4: RECOMENDACIONES | E4: EVIDENCIA | G4: Ranking de Severidad | H4: 0 Sin problemas | I4: 1 Problema estético | J4: 2 Un pequeño problema de usabilidad | K4: 3 Problema importante de usabilidad | L4: 4 Catastrofe de usabilidad
A5: 1. Visibilidad del estado del sistema
A6: Se comunica claramente al usuario todo lo que ocurre en las acciones a lo largo de los flujos | B6: 2 | C6: El feedback existe pero no es parejo. Once páginas usan el sistema de toasts y siete siguen mostrando el error en un <p> inline dentro del formulario. Cinco vistas del colaborador (MisCertificados, Capacitaciones, CursoDetalle, MisDatos, CambiarPassword) no emiten ningún aviso: la acción ocurre y la pantalla simplemente cambia. | D6: Migrar los siete setError restantes a toast y reservar el mensaje inline solo para errores de campo dentro del formulario. Definir la regla en un solo lugar: error de validación = inline junto al campo; resultado de una operación = toast. | E6: client/src/context/ToastContext.jsx; setError inline en Login.jsx, NuevoCurso.jsx, GeneradorIA.jsx, Protocolos.jsx, AsignarCurso.jsx, CambiarPassword.jsx, MisDatos.jsx
A7: El sistema genera confianza comunicando claramente lo que ocurre en cada acción | B7: 1 | C7: Las acciones destructivas sí generan confianza: trece puntos del sistema abren un diálogo de confirmación con título, consecuencia explícita y variante 'danger' en rojo. El hueco está en las acciones exitosas silenciosas, sobre todo la descarga de certificados. | D7: Confirmar con un toast cada operación que termina bien, no solo las que fallan. La descarga de un certificado debería anunciar 'Certificado descargado' igual que anuncia el fallo. | E7: client/src/context/ConfirmContext.jsx; 13 llamadas a confirm() en Profesor.jsx, GestionUsuarios.jsx, GestionSedes.jsx, Practicos.jsx, Protocolos.jsx, GeneradorIA.jsx
A8: Botones significativos al posar puntero del mouse sobre ellos | B8: 1 | C8: Las clases del sistema de diseño (.btn-primary, .btn-outline-dark, .btn-sm, .nav-item, .card-link) tienen hover y transición. Los botones construidos con estilo inline no: paginación, modal de sesión, barra de accesibilidad del login y buena parte del topbar cambian de color solo por estado, nunca al pasar el puntero. | D8: Reemplazar los botones con estilo inline por las clases existentes. Donde el inline sea inevitable, agregar :hover vía clase utilitaria en index.css en lugar de onMouseEnter en JavaScript. | E8: client/src/index.css:277-290 (bloque de hover); Paginacion.jsx:25-32, SessionModal.jsx:25-38, Topbar.jsx:139-197
A9: Se identifican todas las secciones en toda la navegación del sitio | B9: 1 | C9: La sección actual se identifica por tres vías: el rótulo del topbar (prop 'seccion'), el ítem .active del sidebar y el título de página. El breadcrumb, en cambio, existe en una sola pantalla de veinte. | D9: Extender el patrón de breadcrumb de CursoDetalle a las vistas anidadas: NuevoCurso, AsignarCurso, GestionUsuarios, GestionSedes, GeneradorIA y Protocolos. | E9: client/src/components/Topbar.jsx:120; Sidebar.jsx:101; breadcrumb solo en CursoDetalle.jsx:463-478
A10: El tiempo de respuesta es razonable a la acción | B10: 3 | C10: La generación de curso con IA es el punto débil. La pantalla anuncia 'Esto puede tomar 30–60 segundos', pero el timeout del cliente está en 840.000 ms y el propio comentario del código estima ~3 minutos en el caso típico y ~1.300 s en el peor. El usuario ve una mascota animada sin barra de progreso ni indicación de en qué módulo va, durante varios minutos. | D10: Corregir el texto a un rango real y sustituir la espera opaca por progreso por etapas (extrayendo texto → generando módulo 3 de 7 → armando evaluación), alimentado por SSE o polling contra un endpoint de estado. Si el proceso puede superar los 2 minutos, ofrecer además ejecución en segundo plano con aviso al terminar. | E10: client/src/pages/GeneradorIA.jsx:784-785 vs services/api.js:7 (timeout 840000); server/src/routes/ia.js
A11: Al contratar un producto o servicio se informa al usuario que ha completado la acción | B11: 2 | C11: El equivalente a 'completar una contratación' aquí es descargar el certificado, y esa acción no confirma nada al terminar. Si falla, avisa con un alert() nativo del navegador; si funciona, no dice nada. | D11: Sustituir el alert() por toast.error y agregar toast.success al completarse la descarga, con el nombre del archivo generado. | E11: client/src/services/api.js:38-63 (alert en línea 60)
A12: Se identifica el correcto ingreso del usuario en el login | B12: 0 | C12: El login resuelve bien el ingreso correcto: redirige a la home del rol, marca los campos en rojo con aria-invalid cuando falla y anuncia el error con role='alert' para lectores de pantalla. El estado de carga cambia el texto del botón a 'Ingresando...' y lo deshabilita. | D12: Mantener. Como refinamiento, mostrar un toast de bienvenida con el nombre y la sede al aterrizar en el panel, para que el usuario confirme con qué cuenta entró. | E12: client/src/pages/Login.jsx:22-38, 108-160
A13: PROMEDIO | B13: =ROUND(AVERAGE(B6:B12),2)
A14: 2. Coincidencia entre el sistema y el mundo real
A15: La forma de presentar el contenido es familiar y entendible para el usuario | B15: 0 | C15: El contenido está formulado en el vocabulario del sector: ELEAM, sede, estamento, colaborador, protocolo institucional. Las fechas usan formato es-CL y el identificador de acceso es el RUT con su máscara real (12.345.678-9). | D15: Mantener. Al incorporar módulos nuevos, conservar el mismo criterio de nombrar por la tarea del cuidador y no por la entidad de la base de datos. | E15: client/src/pages/Login.jsx:113; Topbar.jsx:265 (toLocaleDateString 'es-CL')
A16: Las funcionalidades tienen un nombre apropiado para que el usuario lo entienda según la idea previa que tiene de éste | B16: 1 | C16: La mayoría de los nombres son transparentes, pero tres términos son internos y no se entienden solos: 'doble fallo', 'cobertura' y 'prácticos'. Existe un componente de tooltip que los explica, y está bien construido (accesible por teclado, cierra con Escape), pero solo se usa en dos de las veinte páginas. | D16: Aplicar el componente Ayuda a cada aparición de esos tres términos, no solo en los paneles de AdminSede y Jefatura. En el sidebar, renombrar 'Prácticos' a 'Prácticos presenciales' para que se entienda sin abrirlo. | E16: client/src/components/Ayuda.jsx; importado solo en AdminSede.jsx y Jefatura.jsx; 'Prácticos' en Sidebar.jsx:32,38,45,58
A17: La terminología utlizada es acorde al lenguaje cultural del usuario | B17: 2 | C17: La plataforma es chilena y tutea en toda la interfaz, salvo dos textos que usan voseo rioplatense: 'Si no elegís, lo asignaremos automáticamente' y 'Creá la primera con el botón de arriba'. Para un cuidador de un ELEAM chileno suenan ajenos y delatan que el texto no fue revisado. | D17: Corregir a 'Si no eliges...' y 'Crea la primera...'. Redactar una guía breve de tono (tuteo chileno, voz activa, sin tecnicismos de sistema) y pasarla por todos los textos de interfaz. | E17: client/src/pages/GeneradorIA.jsx:746; GestionSedes.jsx:128
A18: PROMEDIO | B18: =ROUND(AVERAGE(B15:B17),2)
A19: 3. Dale al usuario el control y la libertad
A20: Existe facilidad al ejecutar las acciones en el sitio | B20: 1 | C20: Los flujos largos están bien resueltos: el alta de curso es un asistente de cuatro pasos con navegación hacia atrás en cada uno, y el detalle de curso separa video, módulos y evaluación en pestañas. La fricción aparece en las listas, donde no hay acciones por lote salvo en gestión de usuarios. | D20: Extender la selección múltiple de GestionUsuarios a la asignación de cursos y a la validación de certificados, que hoy se hacen de a uno. | E20: client/src/pages/NuevoCurso.jsx:141-190; CursoDetalle.jsx:449-459; bulk solo en GestionUsuarios.jsx:546
A21: Se visibilizan las acciones de Deshacer y Rehacer. | B21: 3 | C21: El mecanismo de deshacer existe y está bien hecho — toast.undo muestra la acción revertible durante 5 segundos — pero se usa exactamente una vez en toda la aplicación, al desactivar un usuario. Rechazar un certificado, eliminar un protocolo, descartar el borrador de IA y despublicar un curso son irreversibles sin aviso posterior. | D21: Aplicar toast.undo a todas las acciones destructivas reversibles a nivel de datos. Para las que no lo son (descartar borrador IA), mantener el diálogo de confirmación pero declararlo explícitamente en el mensaje, como ya se hace. | E21: client/src/context/ToastContext.jsx:41-43; único uso en GestionUsuarios.jsx:176; sin undo en Profesor.jsx:366, Protocolos.jsx:54, GeneradorIA.jsx:566
A22: Muestra una forma clara de salir de la acción actual, como un botón Cancelar | B22: 1 | C22: Prácticamente todos los modales y formularios ofrecen Cancelar, y el diálogo de confirmación además cierra con Escape o clic fuera. Falta salida en el proceso más largo: una vez lanzada la generación con IA no hay botón para abortarla, aunque el AbortController ya está implementado internamente. | D22: Exponer el AbortController con un botón 'Cancelar generación' mientras dura el proceso. La infraestructura ya está: solo falta el control visible. | E22: client/src/context/ConfirmContext.jsx:28-37; abortRef en GeneradorIA.jsx:489-491 sin botón asociado
A23: Asegura de que la salida esté claramente etiquetada y sea visible | B23: 1 | C23: Las salidas están etiquetadas con texto, no solo con iconos: 'Volver', 'Cancelar', 'Cerrar sesión', 'Volver al inicio de sesión'. En CursoDetalle el botón Volver usa el historial del navegador, que se rompe al llegar por enlace directo; el código lo reconoce y por eso añadió el breadcrumb como red de seguridad. | D23: Reemplazar navigate(-1) por la ruta explícita del listado en las vistas de detalle, y dejar el historial solo como comportamiento secundario. | E23: client/src/pages/CursoDetalle.jsx:463-478 (breadcrumb) y navigate(-1) en :482
A24: El sitio no debe iniciar procesos sin que el usuario los seleccione explícitamente | B24: 0 | C24: Ninguna operación destructiva se dispara sola. Trece puntos del sistema piden confirmación explícita con el efecto descrito en lenguaje llano ('El colaborador no obtendrá el certificado y deberá volver a rendir la evaluación'). | D24: Mantener el patrón. Al agregar acciones nuevas, usar siempre useConfirm en vez de window.confirm. | E24: client/src/pages/Profesor.jsx:368; GestionUsuarios.jsx:194; GestionSedes.jsx:88
A25: El sitio siempre cuenta con una opción de regreso a la página de inicio | B25: 0 | C25: Hay dos caminos permanentes al inicio: el logo del topbar navega a la home del rol y el primer ítem del sidebar es siempre Inicio, Mis cursos, Resumen o Resumen global según el rol. | D25: Mantener. Añadir cursor-pointer y foco visible al logo para que también sea alcanzable con teclado. | E25: client/src/components/Topbar.jsx:113-118; Sidebar.jsx:27-60
A26: El sitio no debe incluir opciones predeterminadas que pasen inadvertidas para el usuario | B26: 2 | C26: Hay dos valores por omisión que deciden por el usuario. En el generador de IA, el número de módulos queda en 'Automático' y el profesor se asigna solo si el campo se deja vacío — esto último sí está avisado. En el alta de curso, un curso pasa a ser obligatorio por el solo hecho de haber marcado estamentos, sin que la palabra 'obligatorio' aparezca en la decisión. | D26: Hacer explícito el efecto: al marcar estamentos, mostrar 'Este curso será obligatorio para los estamentos seleccionados' antes de publicar, no después. | E26: client/src/pages/NuevoCurso.jsx:98 (obligatorio derivado) vs texto en 448; GeneradorIA.jsx:746,752
A27: PROMEDIO | B27: =ROUND(AVERAGE(B20:B26),2)
A28: 4. Coherencia y estándares
A29: Logo visible e identificable | B29: 0 | C29: El isotipo y el logotipo aparecen en el topbar de todas las vistas autenticadas y en el panel del login, ambos con texto alternativo y ambos accionables hacia el inicio. | D29: Mantener. Añadir un favicon y un título de pestaña por sección para completar la identificación fuera del lienzo de la aplicación. | E29: client/src/assets/logo.js; Topbar.jsx:113-118; Login.jsx:66-72
A30: Identidad y consistencia en las páginas en relación a flujo y arquitectura | B30: 2 | C30: La estructura visual es consistente, pero la arquitectura de URLs no acompaña a los roles. Un administrador de sede que entra al generador de IA o a protocolos navega a /jefatura/ia y /jefatura/protocolos: la URL le dice que está en una sección que no le corresponde. Además conviven copias muertas del código (services/App.jsx y services/pages/) que ya divergieron de las versiones vivas. | D30: Renombrar esas dos rutas a /ia y /protocolos, que es lo que realmente son: funciones compartidas por dos roles. Eliminar client/src/services/App.jsx y client/src/services/pages/ para que no se editen por error. | E30: client/src/components/Sidebar.jsx:45-46,56-57 vs App.jsx:71-72; duplicados en client/src/services/App.jsx y services/pages/
A31: Los símbolos utilizados son posibles de identificar por el usuario y facilitan la interacción con el sitio | B31: 0 | C31: La iconografía es una sola familia (Lucide vía Iconify) y la asociación icono–sección está centralizada en un único mapa, lo que evita que el mismo destino aparezca con iconos distintos en dos lugares. | D31: Mantener el mapa centralizado y extenderlo a los iconos de acción de las tablas, que hoy se declaran caso por caso. | E31: client/src/components/Sidebar.jsx:6-22 (ICON_BY_PATH)
A32: Se dispone de un menú principal con todos los servicios | B32: 2 | C32: El menú no cubre todo lo alcanzable. La ruta /certificados-globales está autorizada para el rol profesor, pero el sidebar del profesor no la incluye: es una función accesible que ningún profesor va a descubrir. A la inversa, no hay ninguna vista para una URL inexistente — todo redirige en silencio al inicio. | D32: Decidir si el profesor debe ver certificados globales y, según eso, agregar el ítem al menú o quitar el rol de la ruta. Añadir una pantalla 404 con enlace al inicio en lugar del redirect mudo. | E32: client/src/App.jsx:43 (ADMIN incluye 'profesor'), :78 y :86; Sidebar.jsx:34-40 sin ese ítem
A33: Los elementos del sistema son ubicados de manera estándar para el fácil reconocimiento del usuario | B33: 2 | C33: Las convenciones están definidas con rigor en index.css (tokens de color, radios, escala de espaciado), pero tres pantallas concentran casi 3.500 líneas con estilo inline que no consume esos tokens. Es el foco desde donde la interfaz se va a desalinear con el tiempo. | D33: Migrar por etapas los estilos inline de GeneradorIA, Profesor y CursoDetalle a clases de index.css, empezando por botones y tarjetas, que son los que más se repiten. | E33: client/src/index.css:1-70 (tokens); GeneradorIA.jsx (1296 líneas), Profesor.jsx (1127), CursoDetalle.jsx (1072)
A34: PROMEDIO | B34: =ROUND(AVERAGE(B29:B33),2)
A35: 5. Prevención de errores
A36: Existen enlaces rotos | B36: 1 | C36: No hay enlaces rotos: cada ruta del sidebar tiene su Route correspondiente en App.jsx y las rutas desconocidas se redirigen. Sí hay un <a href> crudo hacia la biblioteca de protocolos que fuerza una recarga completa de la aplicación en vez de navegar dentro de la SPA. | D36: Cambiar ese <a href> por <Link to>. Añadir una verificación de rutas en el build para que la divergencia sidebar/router no pueda pasar inadvertida. | E36: client/src/pages/GeneradorIA.jsx:697 (<a href='/jefatura/protocolos'>); App.jsx:86 (catch-all)
A37: Existen enlaces que dirigen a otras páginas que no es el propuesto | B37: 2 | C37: Las notificaciones no llevan al objeto que las originó. La función de enrutamiento solo distingue los prácticos; cualquier otra notificación —certificado aprobado, curso asignado, evaluación rechazada— deposita al usuario en la home de su rol, que no es la página de la que hablaba el aviso. | D37: Guardar entidad e id en la notificación y enrutar a la vista concreta: /capacitaciones/:id para un curso, /mis-certificados para un certificado. El caso 'practico' ya demuestra el patrón. | E37: client/src/components/Topbar.jsx:22-25 (rutaPorTipo); uso en :262
A38: Existe un sistema de validación antes de que el usuario envie información para tratar de evitar errores | B38: 2 | C38: Hay validación previa al envío, pero es solo de presencia: se comprueba que el campo no esté vacío. No se valida el formato del RUT ni el del correo pese a que el RUT es la credencial de acceso, y los formularios usan noValidate, con lo que tampoco actúa la validación nativa del navegador. | D38: Añadir validación de formato con feedback en el propio campo: dígito verificador del RUT y patrón de correo. Validar al salir del campo (onBlur), no solo al enviar, para que el error aparezca donde el usuario todavía está mirando. | E38: client/src/pages/Login.jsx:24-27,95; NuevoCurso.jsx:39; GeneradorIA.jsx:485-487
A39: Se ofrece ayuda contextual en tareas complejas | B39: 2 | C39: La ayuda contextual existe en dos formatos —un panel por rol en el topbar y un tooltip reutilizable— pero el tooltip solo llegó a dos pantallas. Las tareas objetivamente más complejas (crear un curso, generar con IA, programar un práctico) no tienen ninguna ayuda dentro del flujo. | D39: Colocar el tooltip en cada campo del asistente de creación de curso y del generador de IA. Añadir una línea de ayuda bajo el título de cada paso explicando qué se decide en ese paso. | E39: client/src/components/Ayuda.jsx; importado solo en AdminSede.jsx y Jefatura.jsx; ausente en NuevoCurso.jsx, GeneradorIA.jsx, Practicos.jsx
A40: El sitio destaca los campos obligatorios a completar y cómo se debe hacer cuando el usuario debe llenar campos | B40: 3 | C40: El marcado de campos obligatorios es irregular. El login usa asterisco rojo con aria-hidden y el alta de curso pone un asterisco suelto sin leyenda que lo explique. Los formularios de prácticos, sedes, protocolos y usuarios no distinguen visualmente lo obligatorio de lo opcional: el usuario lo descubre al enviar. | D40: Unificar: asterisco rojo más leyenda '* campo obligatorio' al inicio de cada formulario, y el atributo required en el input para los lectores de pantalla. Aplicarlo a los siete formularios de la plataforma. | E40: client/src/pages/Login.jsx:98,118 (correcto); NuevoCurso.jsx:196 (asterisco sin leyenda); Practicos.jsx, GestionSedes.jsx, Protocolos.jsx sin marcado
A41: PROMEDIO | B41: =ROUND(AVERAGE(B36:B40),2)
A42: 6. Reconocer en lugar de recordar
...
